[0m23:07:30.416656 [debug] [MainThread]: Sending event: {'category': 'dbt', 'action': 'invocation', 'label': 'start', 'context': [<snowplow_tracker.self_describing_json.SelfDescribingJson object at 0x000001766B2142C0>, <snowplow_tracker.self_describing_json.SelfDescribingJson object at 0x000001766B214440>, <snowplow_tracker.self_describing_json.SelfDescribingJson object at 0x000001766B2143B0>]}


============================== 23:07:30.507695 | aa2a3603-2fe0-4b64-b636-66c7d6b72de6 ==============================
[0m23:07:30.507695 [info ] [MainThread]: Running with dbt=1.8.6
[0m23:07:30.510689 [debug] [MainThread]: running dbt with arguments {'printer_width': '80', 'indirect_selection': 'eager', 'write_json': 'True', 'log_cache_events': 'False', 'partial_parse': 'True', 'cache_selected_only': 'False', 'profiles_dir': 'C:\\Users\\okechukwu.anyanwu\\.dbt', 'fail_fast': 'False', 'debug': 'False', 'log_path': 'logs', 'warn_error': 'None', 'version_check': 'True', 'use_colors': 'True', 'use_experimental_parser': 'False', 'empty': 'None', 'quiet': 'False', 'no_print': 'None', 'warn_error_options': 'WarnErrorOptions(include=[], exclude=[])', 'static_parser': 'True', 'invocation_command': 'dbt init fufu_dbt', 'introspect': 'True', 'target_path': 'None', 'log_format': 'default', 'send_anonymous_usage_stats': 'True'}
[0m23:07:32.055392 [debug] [MainThread]: Starter project path: C:\Users\okechukwu.anyanwu\AppData\Local\anaconda3\Lib\site-packages\dbt\include\starter_project
[0m23:07:32.189681 [info ] [MainThread]: 
Your new dbt project "fufu_dbt" was created!

For more information on how to configure the profiles.yml file,
please consult the dbt documentation here:

  https://docs.getdbt.com/docs/configure-your-profile

One more thing:

Need help? Don't hesitate to reach out to us via GitHub issues or on Slack:

  https://community.getdbt.com/

Happy modeling!

[0m23:07:32.190681 [info ] [MainThread]: Setting up your profile.
[0m23:10:21.161745 [error] [MainThread]: Encountered an error:
list index out of range
[0m23:10:21.625081 [error] [MainThread]: Traceback (most recent call last):
  File "C:\Users\okechukwu.anyanwu\AppData\Local\anaconda3\Lib\site-packages\dbt\cli\requires.py", line 138, in wrapper
    result, success = func(*args, **kwargs)
                      ^^^^^^^^^^^^^^^^^^^^^
  File "C:\Users\okechukwu.anyanwu\AppData\Local\anaconda3\Lib\site-packages\dbt\cli\requires.py", line 101, in wrapper
    return func(*args, **kwargs)
           ^^^^^^^^^^^^^^^^^^^^^
  File "C:\Users\okechukwu.anyanwu\AppData\Local\anaconda3\Lib\site-packages\dbt\cli\main.py", line 470, in init
    results = task.run()
              ^^^^^^^^^^
  File "C:\Users\okechukwu.anyanwu\AppData\Local\anaconda3\Lib\site-packages\dbt\task\init.py", line 347, in run
    self.setup_profile(profile_name)
  File "C:\Users\okechukwu.anyanwu\AppData\Local\anaconda3\Lib\site-packages\dbt\task\init.py", line 262, in setup_profile
    adapter = self.ask_for_adapter_choice()
              ^^^^^^^^^^^^^^^^^^^^^^^^^^^^^
  File "C:\Users\okechukwu.anyanwu\AppData\Local\anaconda3\Lib\site-packages\dbt\task\init.py", line 244, in ask_for_adapter_choice
    return available_adapters[numeric_choice - 1]
           ~~~~~~~~~~~~~~~~~~^^^^^^^^^^^^^^^^^^^^
IndexError: list index out of range

[0m23:10:21.631079 [debug] [MainThread]: Command `dbt init` failed at 23:10:21.630075 after 171.57 seconds
[0m23:10:21.632113 [debug] [MainThread]: Sending event: {'category': 'dbt', 'action': 'invocation', 'label': 'end', 'context': [<snowplow_tracker.self_describing_json.SelfDescribingJson object at 0x000001766B0138C0>, <snowplow_tracker.self_describing_json.SelfDescribingJson object at 0x000001766B3D08F0>, <snowplow_tracker.self_describing_json.SelfDescribingJson object at 0x000001766A7FEB40>]}
[0m23:10:21.633112 [debug] [MainThread]: Flushing usage events
